<?xml version="1.0"?>
<robot name="two_wheel_robot" xmlns:xacro="http://wwww.ros.org/wiki/xacro">

<param name="height" value="0.5 0.3 0.07"/>
<xacro:property name="camera_size" value="0.05"/>

<link name ="chassis">
<!-- 
<inertial>
      <mass value="5"/>
      <origin rpy="0 0 0" xyz="0 0 0.1"/>
      <inertia ixx="0.0395416666667" ixy="0" ixz="0" iyy="0.106208333333" iyz="0" izz="0.106208333333"/>
    </inertial>

  <pose> 0 0 3 0 0 0 </pose>

  <collision name = "collision">
    <geometry>
      <box size = "0.5 0.3 0.07" />
    </geometry>
  </collision>

  <visual name = "visual">
    <origin rpy="0 0 0" xyz="0 0 0"/>
    <geometry>
     <box size = "0.5 0.3 0.07" />
    </geometry>

  </visual> -->

  <inertial>
      <mass value="5"/>
      <origin rpy="0 0 0" xyz="0 0 0.1"/>
      <inertia ixx="0.0395416666667" ixy="0" ixz="0" iyy="0.106208333333" iyz="0" izz="0.106208333333"/>
    </inertial>

    <collision name="collision_chassis">
      <geometry>
        <box size="0.5 0.3 0.07"/>
      </geometry>
    </collision>

    <visual>
      <origin rpy="0 0 0" xyz="0 0 0"/>
      <geometry>
        <box size="0.5 0.3 0.07"/>
      </geometry>
      <material name="blue"/>
    </visual>

  <!-- <collision name="caster">
  <origin rpy=" 0 0 0" xyz="0.35 0 -0.05"/>
    <geometry>
      <sphere radius="0.05"/>
    </geometry>
    <surface>
          <friction>
            <ode>
              <mu>0</mu>
              <mu2>0</mu2>
              <slip1>1.0</slip1>
              <slip2>1.0</slip2>
            </ode>
          </friction>
        </surface>
  </collision>

  <visual name="caster_visual">
        <origin rpy=" 0 0 0" xyz="0.2 0 -0.05"/>
        <geometry>
          <sphere radius="0.05"/>
        </geometry>
    
  </visual> -->


</link>

 


<link name="camera_link">
    <inertial>
      <mass value="1e-5" />
      <origin xyz="0 0 0" rpy="0 0 0"/>
      <inertia ixx="1e-6" ixy="0" ixz="0" iyy="1e-6" iyz="0" izz="1e-6" />
    </inertial>

  <collision name="camera_collison">
    <geometry>
      <box size="${camera_size} ${camera_size} ${camera_size}"/>
      
    </geometry>

  </collision>
  <visual name="camera_visual">
    <geometry>
      <box size="${camera_size} ${camera_size} ${camera_size}"/>
    </geometry>
  </visual>
</link>



<joint name="camera_joint" type="fixed">
<axis xyz="0.0 1.0 0.0"/>
<origin xyz="0.25 0 0.05" rpy="0 0 0"/>
  <parent link="chassis"/>
  <child link="camera_link"/>
  
</joint>

<link name="f_left_wheel">

    <inertial>
      <mass value="0.2"/>
      <origin xyz="0.0 0.0 0.0" rpy="0 1.5707 1.5707"/>
        <inertia ixx="0.000526666666667" ixy="0" ixz="0" iyy="0.000526666666667" iyz="0" izz="0.001"/>
    </inertial>

    <collision name="f_left_wheel_collision"> 
      <origin xyz="0 0 0" rpy="0 1.5707 1.5707"/>
      <geometry>
        
          <cylinder radius="0.1" length="0.04"/>
      </geometry>

    </collision>

  <visual name="f_left_wheel_visual">
    <origin xyz="0.0 0.0 0.0" rpy="0 1.5707 1.5707" />
  <geometry>
    
    <cylinder radius="0.1" length="0.04"/>
  </geometry>

  </visual>

</link>

<joint name="f_left_wheel_joint" type="continuous">

    <origin xyz="0.15 0.2 0.0" rpy="0.0 0.0 0.0"/>
  <axis xyz="0.0 1 0.0" rpy="0.0 0.0 0.0"/>
  <parent link="chassis"/>
  <child link="f_left_wheel"/>
  <limit effort="10000" velocity="1000"/>
        <joint_properties damping="1.0" friction="1.0"/>
</joint>

<link name="f_right_wheel">
  <inertial>

    <mass value="0.2"/>
    <origin xyz="0.0 0.0 0.0" rpy="0 1.5707 1.5707"/>
      <inertia ixx="0.000526666666667" ixy="0" ixz="0" iyy="0.000526666666667" iyz="0" izz="0.001"/>

  </inertial>

  <collision name="f_right_wheel_collision"> 
    <origin xyz="0 0 0" rpy="0 1.5707 1.5707"/>
    <geometry>
      
        <cylinder radius="0.1" length="0.04"/>
    </geometry>

  </collision>

  <visual name="f_right_wheel_visual">
    <origin xyz="0.0 0.0 0.0" rpy="0 1.5707 1.5707" />
  <geometry>
    
    <cylinder radius="0.1" length="0.04"/>
  </geometry>

  </visual>

</link>

<joint name="f_right_wheel_joint" type="continuous">

       <origin xyz="0.15 -0.2 0.0" rpy="0.0 0.0 0.0"/>
  <axis xyz="0.0 1 0.0" rpy="0.0 0.0 0.0"/>
  <parent link="chassis"/>
  <child link="f_right_wheel"/>
  <limit effort="10000" velocity="1000"/>
        <joint_properties damping="1.0" friction="1.0"/>
</joint>




<link name="r_left_wheel">
    <inertial>

      <mass value="0.2"/>
      <origin xyz="0.0 0.0 0.0" rpy="0 1.5707 1.5707"/>
        <inertia ixx="0.000526666666667" ixy="0" ixz="0" iyy="0.000526666666667" iyz="0" izz="0.001"/>

    </inertial>

    <collision name="r_left_wheel_collision"> 
      <origin xyz="0 0 0" rpy="0 1.5707 1.5707"/>
      <geometry>
        
          <cylinder radius="0.1" length="0.04"/>
      </geometry>

    </collision>

  <visual name="r_left_wheel_visual">
    <origin xyz="0.0 0.0 0.0" rpy="0 1.5707 1.5707" />
  <geometry>
    
    <cylinder radius="0.1" length="0.04"/>
  </geometry>

  </visual>

</link>

<joint name="r_left_wheel_joint" type="continuous">

    <origin xyz="-0.15 0.2 0.0" rpy="0.0 0.0 0.0"/>
  <axis xyz="0.0 1 0.0" rpy="0.0 0.0 0.0"/>
  <parent link="chassis"/>
  <child link="r_left_wheel"/>
  <limit effort="10000" velocity="1000"/>
        <joint_properties damping="1.0" friction="1.0"/>
</joint>


<link name="r_right_wheel">
  <inertial>

    <mass value="0.2"/>
    <origin xyz="0.0 0.0 0.0" rpy="0 1.5707 1.5707"/>
      <inertia ixx="0.000526666666667" ixy="0" ixz="0" iyy="0.000526666666667" iyz="0" izz="0.001"/>

  </inertial>

  <collision name="r_right_wheel_collision"> 
    <origin xyz="0 0 0" rpy="0 1.5707 1.5707"/>
    <geometry>
      
        <cylinder radius="0.1" length="0.04"/>
    </geometry>

  </collision>

  <visual name="r_right_wheel_visual">
    <origin xyz="0.0 0.0 0.0" rpy="0 1.5707 1.5707" />
  <geometry>
    
    <cylinder radius="0.1" length="0.04"/>
  </geometry>

  </visual>

</link>

<joint name="r_right_wheel_joint" type="continuous">

       <origin xyz="-0.15 -0.2 0.0" rpy="0.0 0.0 0.0"/>
  <axis xyz="0.0 1 0.0" rpy="0.0 0.0 0.0"/>
  <parent link="chassis"/>
  <child link="r_right_wheel"/>
  <limit effort="10000" velocity="1000"/>
        <joint_properties damping="1.0" friction="1.0"/>
</joint> 



<!-- 
 <collision name="collision_chassis">
      <geometry>
        <box size="0.5 0.3 0.07"/>
      </geometry>
    </collision>
    <visual>
      <origin rpy="0 0 0" xyz="0 0 0"/>
      <geometry>
        <box size="0.5 0.3 0.07"/>
      </geometry>
    </visual> -->

<gazebo>
<!-- <plugin filename="libgazebo_ros_diff_drive.so" name="differential_drive_controller">
      <alwaysOn>true</alwaysOn>
      <updateRate>20</updateRate>
      <leftJoint>left_wheel_joint</leftJoint>
      <rightJoint>right_wheel_joint</rightJoint>
      <wheelSeparation>0.4</wheelSeparation>
      <wheelDiameter>0.2</wheelDiameter>
      <torque>0.1</torque>
      <commandTopic>cmd_vel</commandTopic>
      <odometryTopic>odom</odometryTopic>
      <odometryFrame>odom</odometryFrame>
      <robotBaseFrame>chassis</robotBaseFrame>

</plugin> -->
<plugin name="skid_steer_drive_controller" filename="libgazebo_ros_skid_steer_drive.so">
    <updateRate>20</updateRate>
    <robotNamespace>/</robotNamespace>
    <leftFrontJoint>f_left_wheel_joint</leftFrontJoint>
    <rightFrontJoint>f_right_wheel_joint</rightFrontJoint>
    <leftRearJoint>r_left_wheel_joint</leftRearJoint>
    <rightRearJoint>r_right_wheel_joint</rightRearJoint>
    <wheelSeparation>0.6</wheelSeparation>
    <wheelDiameter>0.2</wheelDiameter>
    <robotBaseFrame>chassis</robotBaseFrame>
    <torque>10</torque>
    <commandTopic>cmd_vel</commandTopic>
    <broadcastTF>false</broadcastTF>
        <covariance_x>0.0001</covariance_x>
    <covariance_y>0.0001</covariance_y>
    <covariance_yaw>0.01</covariance_yaw>
  </plugin> 
</gazebo>

<gazebo reference="camera_link">

  <sensor type="camera" name="camera1">
    <update_rate> 30.0 </update_rate>
    <camera name="head">
    <horizontal_fov>1.3962634</horizontal_fov>
        <image>
          <width>800</width>
          <height>800</height>
          <format>R8G8B8</format>
        </image>
        <clip>
          <near>0.02</near>
          <far>300</far>
        </clip>
        <noise>
          <type>gaussian</type>
          <!-- Noise is sampled independently per pixel on each frame.
               That pixel's noise value is added to each of its color
               channels, which at that point lie in the range [0,1]. -->
          <mean>0.0</mean>
          <stddev>0.007</stddev>
        </noise>
    </camera>
    <plugin name="camera_controller" filename="libgazebo_ros_camera.so">
        <alwaysOn>true</alwaysOn>
        <updateRate>0.0</updateRate>
        <cameraName>rrbot/camera1</cameraName>
        <imageTopicName>image_raw</imageTopicName>
        <cameraInfoTopicName>camera_info</cameraInfoTopicName>
        <frameName>camera_link</frameName>
        <hackBaseline>0.07</hackBaseline>
        <distortionK1>0.0</distortionK1>
        <distortionK2>0.0</distortionK2>
        <distortionK3>0.0</distortionK3>
        <distortionT1>0.0</distortionT1>
        <distortionT2>0.0</distortionT2>
      </plugin>
  </sensor>
</gazebo>

</robot>